Workbook

Sheet Overview
A1: CanDoItAll Process Management — Execution Grade
A2: Process-first bundle for direct implementation inside CanDoItAll. This revision hardens the model around process-native orchestration, governed baton/work-brief handoffs, live canvas supervision as a projection, and explicit convergence rules for CRM-HR, Workspace, Projects, and future AgentFramework integration.
A4: Metric | B4: Value | C4: Note
A5: Feature count | B5: =COUNTA(Features!A5:A2000) | C5: Number of planned process-management features in this bundle.
A6: User story count | B6: =COUNTA(UserStories!A5:A5000) | C6: User stories captured from the thread, repo inspection, and review passes.
A7: Risk count | B7: =COUNTA(Risks!A5:A2000) | C7: Tracked delivery, governance, and operating-model risks.
A8: Decision count | B8: =COUNTA(ADRs!A5:A2000) | C8: Architecture decisions intentionally locked by this bundle.
A9: Wave count | B9: =COUNTA(DeliveryWaves!A5:A2000) | C9: Planned implementation waves.
A10: Critical features | B10: =COUNTIF(Features!D5:D2000,"Critical") | C10: Critical items to ship early or treat as cross-cutting.
A11: Operational coverage points | B11: =COUNTA(OperationalCoverage!A5:A2000) | C11: Large-enterprise process-management concerns explicitly mapped in the bundle.
A12: Recommended sequence: approve the process-first decisions, implement Wave 1 authoring/modeling + ownership + staffing first, then runtime/governance, then telemetry/conformance.
A14: Key bundle conclusions
A15: Conclusion | B15: Decision
A16: Canonical owner | B16: Create `CanDoItAll.Modules.Processes` as a new canonical module.
A17: Storage | B17: Use shared AppDbContext first with `Processes_*` tables and keep SQLite/PostgreSQL parity.
A18: Actors | B18: Bind process actors to CRM-HR parties and AI-agent profiles; do not duplicate identity.
A19: Staffing | B19: Managers define reusable role/agent templates in CRM-HR; HR fulfills process gaps from those templates.
A20: Ownership | B20: Governed processes must carry process owner, customer, criticality, and interface metadata.
A21: Design principle | B21: Model value flow and interfaces, not the org chart.
A22: Exceptions | B22: Input-quality rules, variants, exceptions, and decision rights are first-class.
A23: Metrics | B23: Measure lead/touch/queue/rework/customer outcome, not just activity counts.
A24: Reality check | B24: Conformance review compares official process with runtime evidence and governed observations.
A25: Canvas | B25: Reuse CanvasLib and Prompt Factory-style adapters for interactive process modeling.

Sheet RepoFit
A1: Repo fit and observed seams
A2: Observed implementation seams from the uploaded CanDoItAll and AgentFramework repositories after the process-native orchestration review.
A4: Area / Module | B4: Current asset | C4: Why it matters for Processes | D4: Integration direction | E4: Planned wave | F4: Source paths
A5: Projects | B5: Project models, hierarchy, project UX, project modal/board | C5: Project-scoped processes, shared-project navigation, explicit process ownership for shared libraries/projects, and typed links from process definitions/runs/steps into project context without replacing project hierarchy. | D5: Processes -> Projects (reference ProjectId and context links); Projects UX -> Processes navigation | E5: Wave 1/3 | F5: Yes | G5: src/CanDoItAll.Modules.Projects/ProjectModels.cs; ProjectModalHost.razor; ProjectsBoard.razor
A6: CRM-HR | B6: Party directory, AI-agent profiles, project assignments, workforce/staffing primitives | C6: Actor role binding, owner/steward binding, manager-owned role and agent templates, durable AI identities, approvers, supervisory parties, staffing fulfillment, and future AI-executor mapping. | D6: Processes -> CRM-HR via bridge; CRM-HR owns identities, staffing templates, and AI business profiles | E6: Wave 1/2 | F6: Yes | G6: src/CanDoItAll.Modules.CrmHr/CrmHrBusinessModels.cs; CrmHrServices.cs; Pages/CrmHrAgentsPage.razor; Pages/CrmHrAssignmentsPage.razor
A7: CRM-HR Workforce / Recruiting / Assignments | B7: Staffing requests, workforce profiles, recruiting pipelines, onboarding tasks, capacity dashboard | C7: Manager-defined role templates, staffing briefs from process gaps, candidate/agent sourcing, capacity-aware suggestions, fallback handoffs, and capacity signals used by process telemetry. | D7: Processes <-> CRM-HR staffing bridges | E7: Wave 1/2 | F7: Yes | G7: src/CanDoItAll.Modules.CrmHr/CrmHrBusinessModels.cs; CrmHrServices.cs; CrmHrRecruitingServices.cs; Pages/CrmHrAssignmentsPage.razor; Pages/CrmHrRecruitingPage.razor; Pages/CrmHrWorkforcePage.razor
A8: Workspace | B8: Shared provider profiles, neutral provider contract, provider execution service, settings surface | C8: Future AI executor bindings and CRM-HR agent profiles must resolve through shared Workspace provider profiles instead of inventing a second permanent provider registry. | D8: Processes -> Workspace provider/profile references; CRM-HR and future AF bridge reuse Workspace truth | E8: Wave 1/3 | F8: Yes | G8: src/CanDoItAll.Modules.Workspace/WorkspaceModels.cs; ProviderExecution.cs; Pages/SettingsPage.razor
A9: Workbench | B9: Project structure surface, projection/bindings, leases, Mermaid import | C9: Optional process summary projections and navigation; import/export heuristics as reference only. | D9: Processes -> Workbench projection; never canonical reverse | E9: Wave 3 | F9: No | G9: architecture/adrs/ADR-0002*; ADR-0004*; ProjectStructureImportService.cs; ProjectStructureLeaseService.cs
A10: CanvasLib | B10: Interactive workbench-style canvas foundation | C10: Dedicated process designer surface, diagram layout, quick-create, minimap, grouping, possible link-label extension. | D10: Processes -> CanvasLib adapter | E10: Wave 1 | F10: Yes | G10: src/CanDoItAll.Components.CanvasLib/Canvas/Workbench/*
A11: Factory | B11: Prompt Flow templates and graph/canvas adapters | C11: Reference pattern for graph editor UX and optional starter template seeding from prompt-flow patterns. | D11: Processes <- Factory patterns / seeds | E11: Wave 1/2 | F11: No | G11: src/CanDoItAll.Modules.Factory/FactoryDomain.cs; CanvasAdapters/*; output/prompt-library/factory-prompt-flow-templates.seed.json
A12: Activity | B12: Shared activity timeline | C12: Record high-level run events, change-governance communications, and conformance review signals. | D12: Processes -> Activity via IActivityStream | E12: Wave 2/3/4 | F12: Yes | G12: src/CanDoItAll.SharedKernel/ActivityStream.cs; src/CanDoItAll.Modules.Activity/ActivityModels.cs
A13: Automation | B13: Background runtime and automation signals | C13: Overdue/blocker signals, governed change notifications, and later scheduled transitions or telemetry extraction jobs. | D13: Processes -> Automation signals | E13: Wave 3/4 | F13: No | G13: src/CanDoItAll.SharedKernel/AutomationSignals.cs; src/CanDoItAll.Modules.Automation/*
A14: Validation | B14: Validation center and review artifacts | C14: Attach validation gates, reviews, input-quality requirements, and evidence requirements to steps. | D14: Processes <-> Validation references | E14: Wave 3 | F14: No | G14: src/CanDoItAll.Modules.Validation/*
A15: TestLab | B15: Test plans and evidence | C15: Attach test plans/evidence to steps and completion gates. | D15: Processes <-> TestLab references | E15: Wave 3 | F15: No | G15: src/CanDoItAll.Modules.TestLab/*
A16: SharedKernel | B16: Cross-module contracts, project object types, activity and automation contracts | C16: Introduce process bridge contracts, process portfolio object types, and shared activity/automation contracts for telemetry and governance. | D16: Processes -> SharedKernel contracts | E16: Wave 1/3 | F16: Yes | G16: src/CanDoItAll.SharedKernel/ProjectObjectContracts.cs; ActivityStream.cs; AutomationSignals.cs
... A19: AgentFramework overlay | B19: Research runtime, temporary template/provider/capability/session stores, rights model, sessions, execution logs, metrics | C19: Future AI-execution bridge, process-bound correlation, permission mapping, and registry convergence; business templates and durable identities stay outside the overlay. | D19: Future adapter only; Processes remains canonical for orchestration, CRM-HR/Workspace remain canonical for identities/templates/providers | E19: Wave 3+ | F19: No | G19: CanDoItAll.AgentFramework-main/integration-map/01-candoitall-seams.md; integration-map/02-data-rights-and-persistence.md; src/CanDoItAll.AgentFramework.Models/AgentModels.cs; src/CanDoItAll.AgentFramework.Models/ConversationModels.cs; src/CanDoItAll.AgentFramework.Core/AgentFrameworkWorkspaceService.Chat.cs

Sheet Features
A1: Feature catalog
A2: Execution-grade process-management feature set prioritized for direct implementation, including process-native orchestration and future AgentFramework convergence guardrails.
A4: ID | B4: Title | C4: Summary | D4: Priority | E4: Wave | F4: Dependencies | G4: Acceptance summary | H4: Repo touchpoints (sample)
A5: PRM-F01 | B5: Process module foundation and shell integration | C5: Introduce a new canonical CanDoItAll module for process management, register it in composition, expose shell and project routes, and keep the module isolated from Workbench canonical state. | D5: Critical | E5: Wave 1 | G5: A top-level /processes route exists and renders without breaking current shell navigation. | A project-scoped route exists for process work and can be opened from project UX. | The module is registered through the same composition pattern as existing CanDoItAll modules. | SQLite and PostgreSQL migrations compile with the new module present. | H5: src/CanDoItAll.Modules.Processes/CanDoItAll.Modules.Processes.csproj (new) | src/CanDoItAll.Modules.Processes/ProcessesModuleServiceCollectionExtensions.cs (new) | src/CanDoItAll.Web/Program.cs | src/CanDoItAll.Web/Composition/ShellNavigation.cs | src/CanDoItAll.Composition/CanDoItAll.Composition.csproj | src/CanDoItAll.Composition/ModuleAssemblies.cs | src/CanDoItAll.Migrations.Sqlite/* | src/CanDoItAll.Migrations.PostgreSql/* | tests/CanDoItAll.Tests.*
A6: PRM-F02 | B6: Process definition language and versioning | C6: Create the canonical process DSL with definitions, versions, nodes, transitions, lifecycle status, publication rules, and template cloning semantics. | D6: Critical | E6: Wave 1 | F6: PRM-F01 | G6: Process definitions support draft, published, and archived versions. | Published versions are immutable and draft edits produce a new working version. | Definitions can be scoped as workspace templates or project-owned processes. | The canonical graph is stored outside Workbench metadata. | H6: src/CanDoItAll.Modules.Processes/ProcessDomain.cs (new) | src/CanDoItAll.Modules.Processes/ProcessDefinitionServices.cs (new) | src/CanDoItAll.Modules.Processes/ProcessVersioningServices.cs (new) | src/CanDoItAll.Modules.Processes/ProcessesSchemaInitializer.cs (new) | tests/CanDoItAll.Tests.Integration/ProcessesServiceIntegrationTests.cs (new) | tests/CanDoItAll.Tests.Unit/ProcessDefinitionLanguageTests.cs (new)
A7: PRM-F03 | B7: Actor roles, responsibilities, and CRM-HR bindings | C7: Bind process actors to CRM-HR parties and AI-agent profiles, model role responsibilities, and prevent creation of a second durable agent registry inside the process module. | D7: Critical | E7: Wave 1 | F7: PRM-F01, PRM-F02 | G7: A process step can reference responsible, consulted, approver, and observer roles. | Roles can bind to CRM-HR parties and AI-agent profiles without duplicating durable identity. | Actor rebinding preserves auditability of earlier runs. | Future AI execution metadata can be attached without introducing a runtime dependency on AgentFramework. | H7: src/CanDoItAll.Modules.Processes/ProcessActorModels.cs (new) | src/CanDoItAll.Modules.Processes/ProcessActorServices.cs (new) | src/CanDoItAll.Modules.CrmHr/CrmHrModuleServiceCollectionExtensions.cs | src/CanDoItAll.Modules.CrmHr/CrmHrServices.cs | src/CanDoItAll.Modules.CrmHr/Pages/CrmHrAgentsPage.razor | tests/CanDoItAll.Tests.Integration/ProcessesCrmHrIntegrationTests.cs (new)
A8: PRM-F16 | B8: Role and agent templates, staffing briefs, and sourcing handoffs | C8: Let managers define reusable human/AI/hybrid role templates in CRM-HR, let process designers reference them instead of ad-hoc free-text roles, and let HR fulfill gaps through staffing, recruiting, or agent-sourcing workflows with durable snapshots. | D8: Critical | E8: Wave 1 | F8: PRM-F03 | G8: A process actor role can optionally reference a reusable manager-approved role/agent template instead of free-text only. | Templates capture modality, required skills/capabilities, allocation intent, and fallback/supervisory expectations. | HR can open staffing, recruiting, or AI-agent sourcing work from unresolved process role gaps without losing process context. | Role/agent templates support governed lifecycle states (draft/active/retired) without rewriting history. | Published process versions snapshot the selected template version and key requirement summary. | Runs snapshot the resolved assignee, eligible pool/fallback metadata, and rebind reasons. | AI-oriented templates still resolve through CRM-HR identities and future execution bridges rather than direct runtime coupling. | H8: src/CanDoItAll.Modules.CrmHr/CrmHrBusinessModels.cs | src/CanDoItAll.Modules.CrmHr/CrmHrServices.cs | src/CanDoItAll.Modules.CrmHr/CrmHrRecruitingServices.cs | src/CanDoItAll.Modules.CrmHr/Pages/CrmHrAssignmentsPage.razor | src/CanDoItAll.Modules.CrmHr/Pages/CrmHrWorkforcePage.razor | src/CanDoItAll.Modules.CrmHr/Pages/CrmHrAgentsPage.razor | src/CanDoItAll.Modules.CrmHr/Pages/CrmHrRoleTemplatesPage.razor (new) | src/CanDoItAll.Modules.Processes/ProcessActorTemplateBridge.cs (new) | src/CanDoItAll.Modules.Processes/ProcessActorServices.cs | src/CanDoItAll.Modules.Processes/Pages/ProcessDesignerPage.razor
A9: PRM-F04 | B9: Step contracts, inputs, outputs, and evidence | C9: Define typed step contracts for what a step consumes, produces, validates, and hands off so responsibilities are explicit and auditable. | D9: High | E9: Wave 1 | F9: PRM-F02, PRM-F03 | G9: Each step can declare entry criteria, exit criteria, expected artifacts, and evidence requirements. | Steps can declare reusable input and output contracts with type, cardinality, and notes. | Reviewers can see required evidence before completion is allowed. | Contract data is queryable separately from the diagram layout. | H9: src/CanDoItAll.Modules.Processes/ProcessContractModels.cs (new) | src/CanDoItAll.Modules.Processes/ProcessContractServices.cs (new) | src/CanDoItAll.Modules.Validation/* (integration hooks) | src/CanDoItAll.Modules.TestLab/* (integration hooks) | tests/CanDoItAll.Tests.Integration/ProcessContractIntegrationTests.cs (new)
A10: PRM-F17 | B10: Process ownership, interfaces, customer, and value alignment | C10: Make process owner, sponsor, customer, strategic objective, criticality, and upstream/downstream interfaces first-class so processes are governed end-to-end by value flow rather than org-chart convenience. | D10: Critical | E10: Wave 1 | F10: PRM-F02, PRM-F03, PRM-F04 | G10: A process definition cannot be published without a process owner, primary customer, criticality tier, and value statement. | Process definitions can declare sponsor, stewarding managers, strategic objective links, and upstream/downstream interface contracts. | Interface contracts capture sender, receiver, required inputs/outputs, definition of done, and handoff expectation metadata. | Actor assignments remain separate from org hierarchy; the model does not force the process graph to mirror reporting lines. | Shared-project or shared-library processes preserve explicit ownership instead of being duplicated as shadow copies. | H10: src/CanDoItAll.Modules.Processes/ProcessGovernanceModels.cs (new) | src/CanDoItAll.Modules.Processes/ProcessPortfolioServices.cs (new) | src/CanDoItAll.Modules.Processes/ProcessInterfaceServices.cs (new) | src/CanDoItAll.Modules.Processes/Pages/ProcessGovernancePage.razor (new) | src/CanDoItAll.Modules.Processes/Pages/ProcessDesignerPage.razor | src/CanDoItAll.Modules.Projects/ProjectModels.cs | src/CanDoItAll.Modules.CrmHr/CrmHrServices.cs | src/CanDoItAll.SharedKernel/ProjectObjectContracts.cs | tests/CanDoItAll.Tests.Integration/ProcessOwnershipIntegrationTests.cs (new) | tests/CanDoItAll.Tests.Component/ProcessGovernanceEditorTests.cs (new)
A11: PRM-F09 | B11: Canvas modeler and interactive diagrams | C11: Deliver a dedicated process designer on top of CanvasLib with reusable node rendering, quick-create affordances, saved layout, template-aware role editing, and a path to labeled transitions and swimlane-like grouping. | D11: Critical | E11: Wave 1 | F11: PRM-F01, PRM-F02, PRM-F03 | G11: Users can create and edit process nodes and transitions from an interactive canvas surface. | Diagram layout persists independently from the canonical graph semantics. | Phase grouping and actor grouping can be represented without forcing Workbench to be the source of truth. | Wave 1 designer delivery is not blocked by later handoff-label chrome; handoff visuals can deepen in Wave 2. | The design leaves room for labeled transitions and swimlane extensions where CanvasLib needs them. | H11: src/CanDoItAll.Modules.Processes/CanvasAdapters/ProcessCanvasGraphAdapter.cs (new) | src/CanDoItAll.Modules.Processes/Pages/ProcessDesignerPage.razor (new) | src/CanDoItAll.Components.CanvasLib/Canvas/Workbench/CanvasWorkbenchSurface.cs | src/CanDoItAll.Components.CanvasLib/Canvas/Workbench/CanvasWorkbenchNode.cs | src/CanDoItAll.Components.CanvasLib/Canvas/Workbench/CanvasWorkbenchEvents.cs | src/CanDoItAll.Modules.Factory/CanvasAdapters/* (reference pattern) | tests/CanDoItAll.Tests.Components/ProcessDesignerPageTests.cs (new) | tests/CanDoItAll.Tests.Playwright/ProcessModelingFlowTests.cs (new)
A12: PRM-F15 | B12: Storage, migrations, and performance hardening | C12: Use the shared CanDoItAll app database first, add strong indexing and retention boundaries, and leave a clean seam for later extraction of hot append-only stores. | D12: Critical | E12: Cross-cutting | F12: PRM-F01, PRM-F02, PRM-F07, PRM-F08 | G12: Process tables live in the main app database with consistent naming and indexing conventions. | SQLite remains supported for local users without extra setup. | PostgreSQL migrations exist and stay in lockstep with SQLite. | The journal and runtime tables have a defined retention/extraction seam for future scale. | H12: src/CanDoItAll.Infrastructure/Persistence/AppDbContext.cs | src/CanDoItAll.Migrations.Sqlite/* | src/CanDoItAll.Migrations.PostgreSql/* | tests/CanDoItAll.Tests.Integration/* database profile coverage | tests/CanDoItAll.Tests.Playwright/AppSmokeTests.DatabaseProfiles.cs
A13: PRM-F05 | B13: Transition rules, decisions, and explicit handoffs | C13: Model ordered responsibility changes between actors, decision branches, retries, default paths, and explicit handoff payloads for process execution. | D13: Critical | E13: Wave 2 | F13: PRM-F02, PRM-F03, PRM-F04 | G13: Decision paths can carry condition text, default-path markers, and branch priority. | Handoffs record source actor, target actor, payload summary, and completion reason. | The engine rejects invalid graphs such as unreachable end states or orphaned transitions. | Sequential specialized handoffs are first-class even before AgentFramework runtime integration. | H13: src/CanDoItAll.Modules.Processes/ProcessTransitionServices.cs (new) | src/CanDoItAll.Modules.Processes/ProcessValidationServices.cs (new) | tests/CanDoItAll.Tests.Unit/ProcessTransitionRulesTests.cs (new) | tests/CanDoItAll.Tests.Integration/ProcessHandoffIntegrationTests.cs (new)
A14: PRM-F06 | B14: Approval policies, escalations, and governance gates | C14: Add approval gates, escalation rules, separation-of-duties constraints, and policy boundaries that align with future agent-rights enforcement while working for human and manual flows now. | D14: High | E14: Wave 2 | F14: PRM-F03, PRM-F04, PRM-F05 | G14: A process run can pause awaiting approval and resume with an auditable decision. | Escalation routes can target a human party or supervisory role. | Policy metadata is explicit and not hidden inside runtime-only configuration. | Approval policies can prevent self-approval or conflicting role combinations unless an explicit override path is configured. | The model can later map to agent external-call approvals and collaboration rights. | H14: src/CanDoItAll.Modules.Processes/ProcessPolicyModels.cs (new) | src/CanDoItAll.Modules.Processes/ProcessApprovalServices.cs (new) | src/CanDoItAll.SharedKernel/ActivityStream.cs | tests/CanDoItAll.Tests.Integration/ProcessApprovalIntegrationTests.cs (new)
A15: PRM-F07 | B15: Runtime execution state machine and assignments | C15: Implement process runs, step runs, state transitions, actor claims, eligibility-aware assignments, and safe concurrency rules for manual, AI, and hybrid execution. | D15: Critical | E15: Wave 2 | F15: PRM-F02, PRM-F03, PRM-F04, PRM-F05, PRM-F06 | G15: A process run can start from a published definition version and keep that version immutable for the run lifetime. | Only valid state transitions are allowed for runs and steps. | Conflicting claims and double completions are rejected deterministically. | Assignment resolution can consider eligible pools, capacity/validation state, and fallback routes before work is claimed or rebound. | Manual, human-approved, and AI-backed executors all fit the same state machine. | H15: src/CanDoItAll.Modules.Processes/ProcessRunModels.cs (new) | src/CanDoItAll.Modules.Processes/ProcessRuntimeServices.cs (new) | src/CanDoItAll.Modules.Processes/ProcessLeaseService.cs (new) | src/CanDoItAll.Modules.Workbench/ProjectStructureLeaseService.cs (reference pattern) | tests/CanDoItAll.Tests.Integration/ProcessRuntimeIntegrationTests.cs (new)
A16: PRM-F08 | B16: Execution timeline, audit journal, and replay | C16: Persist append-oriented events for every important runtime change so project, manager, QA, and future training flows can replay what happened. | D16: High | E16: Wave 2 | F16: PRM-F07 | G16: Every run change emits a durable process event with actor and reason metadata. | High-level process events appear on the shared activity stream. | A replay API can reconstruct step order and handoff decisions from journaled events. | Journal writes are separated from mutable current-state rows. | H16: src/CanDoItAll.Modules.Processes/ProcessEventJournal.cs (new) | src/CanDoItAll.Modules.Activity/ActivityModels.cs | src/CanDoItAll.SharedKernel/ActivityStream.cs | tests/CanDoItAll.Tests.Integration/ProcessJournalIntegrationTests.cs (new) | tests/CanDoItAll.Tests.Unit/ProcessReplayTests.cs (new)
A17: PRM-F18 | B17: Variants, exceptions, input quality, and decision rights | C17: Model controlled variants, exception paths, input-quality requirements, explicit decision rights, and risk-based controls so the runtime handles real-world deviations without degenerating into bureaucracy. | D17: High | E17: Wave 2 | F17: PRM-F04, PRM-F05, PRM-F06, PRM-F07, PRM-F17 | G17: Steps can define mandatory inputs, completeness checks, and structured rejection/rework reasons before execution continues. | The model distinguishes normal path, approved variant, and exception path metadata with escalation or override requirements. | Decision rights are explicit: who can decide, under what threshold or rule, with what evidence, and through which override route. | Controls can be tagged as mandatory, conditional, or optional based on risk tier so low-risk work is not over-approved. | Runtime journals capture exception reasons, overrides, and input-quality failures separately from generic failure states. | H17: src/CanDoItAll.Modules.Processes/ProcessInputQualityModels.cs (new) | src/CanDoItAll.Modules.Processes/ProcessExceptionServices.cs (new) | src/CanDoItAll.Modules.Processes/ProcessDecisionRightsService.cs (new) | src/CanDoItAll.Modules.Processes/ProcessPolicyModels.cs | src/CanDoItAll.Modules.Validation/* | src/CanDoItAll.Modules.Security/SecurityModels.cs | tests/CanDoItAll.Tests.Unit/ProcessExceptionRuleTests.cs (new) | tests/CanDoItAll.Tests.Integration/ProcessDecisionRightsIntegrationTests.cs (new)
... A28: PRM-F21 | B28: Conformance, field observation, and reality-alignment reviews | C28: Compare modeled processes with actual execution and field observations, capture deviations and unofficial workarounds, and turn them into governed improvement work so the system reflects reality instead of only diagrams. | D28: High | E28: Wave 4 | F28: PRM-F08, PRM-F11, PRM-F19, PRM-F20 | G28: Reviewers can record conformance observations against runs or process versions with structured deviation reasons. | The system can cluster repeated unofficial loops, extra handoffs, and bypass patterns from journals for owner review. | Observation notes support restricted visibility and privacy-safe governance handling; there is no unmanaged rumor registry. | Process owners can convert deviation clusters into approved variants, fixes, or policy-breach investigations. | Conformance reporting can show paper-versus-reality deltas by step, interface, owner, customer segment, or project. | H28: src/CanDoItAll.Modules.Processes/ProcessConformanceModels.cs (new) | src/CanDoItAll.Modules.Processes/ProcessConformanceService.cs (new) | src/CanDoItAll.Modules.Processes/Pages/ProcessConformancePage.razor (new) | src/CanDoItAll.Modules.Security/SecurityModels.cs | src/CanDoItAll.SharedKernel/ActivityStream.cs | tests/CanDoItAll.Tests.Integration/ProcessConformanceIntegrationTests.cs (new) | tests/CanDoItAll.Tests.Playwright/ProcessConformanceReviewFlowTests.cs (new)

Sheet UserStories
A1: User stories
A2: Detailed user stories derived from the thread, repo-fit inspection, and senior review passes.
A4: Story ID | B4: Feature ID | C4: Actor | D4: Story | E4: Benefit | F4: Priority | G4: Wave
A5: US-PRM-001 | B5: PRM-F01 | C5: Workspace operator | D5: As a workspace operator, I want a top-level Processes surface in the CanDoItAll shell so that process management becomes a first-class module instead of hidden inside another area. | E5: discoverability | F5: Critical | G5: Wave 1
A6: US-PRM-002 | B6: PRM-F01 | C6: Project member | D6: As a project member, I want to open project-scoped processes from project UX so that process work stays anchored to the owning project. | E6: project anchoring | F6: Critical | G6: Wave 1
A7: US-PRM-003 | B7: PRM-F01 | C7: Developer | D7: As a developer, I want the new module to follow existing module registration patterns so that composition, DI, and migrations remain predictable. | E7: maintainability | F7: High | G7: Wave 1
A8: US-PRM-004 | B8: PRM-F01 | C8: Architect | D8: As an architect, I want process management isolated as a canonical module so that Workbench does not absorb yet another business-owned truth model. | E8: model integrity | F8: Critical | G8: Wave 1
A9: US-PRM-005 | B9: PRM-F02 | C9: Process designer | D9: As a process designer, I want to create a draft process definition with name, purpose, scope, and owner so that I can iteratively model delivery flows before publishing them. | E9: drafting | F9: Critical | G9: Wave 1
A10: US-PRM-006 | B10: PRM-F02 | C10: Process designer | D10: As a process designer, I want published versions to become immutable so that process runs always reference a stable definition snapshot. | E10: reproducibility | F10: Critical | G10: Wave 1
A11: US-PRM-007 | B11: PRM-F02 | C11: Delivery lead | D11: As a delivery lead, I want to clone a reusable workspace template into a project so that recurring process patterns can be reused without manual recreation. | E11: reuse | F11: High | G11: Wave 1
A12: US-PRM-008 | B12: PRM-F02 | C12: Reviewer | D12: As a reviewer, I want obsolete process versions archived rather than silently overwritten so that governance and audit history remain visible. | E12: governance | F12: High | G12: Wave 1
A13: US-PRM-009 | B13: PRM-F03 | C13: CRM-HR administrator | D13: As a CRM-HR administrator, I want process actor roles to bind to existing parties and AI-agent profiles so that durable identity stays in CRM-HR. | E13: identity consistency | F13: Critical | G13: Wave 1
A14: US-PRM-010 | B14: PRM-F03 | C14: Process designer | D14: As a process designer, I want to assign responsible, consulted, approver, and observer roles to steps so that accountability is explicit. | E14: responsibility clarity | F14: Critical | G14: Wave 1
A15: US-PRM-011 | B15: PRM-F03 | C15: Project lead | D15: As a project lead, I want to rebind a process role when a human or agent changes so that the process survives staffing changes without losing history. | E15: operational continuity | F15: High | G15: Wave 1
... A106: US-PRM-102 | B106: PRM-F23 | C106: Governance owner | D106: As a governance owner, I want process step policy to constrain future agent permissions and approvals so runtime autonomy never bypasses modeled decision rights. | E106: policy enforcement | F106: High | G106: Wave 3

Sheet Risks
A1: Risk register
A2: Architecture, delivery, governance, and operating-model risks for the process-management implementation.
A4: Risk ID | B4: Title | C4: Description | D4: Impact | E4: Likelihood | F4: Owner | G4: Mitigation | H4: Related features
A5: R-PRM-01 | B5: Workbench becomes hidden canonical store | C5: Process identity or runtime data leaks into Workbench metadata or node state because projection shortcuts feel convenient. | D5: High | E5: Medium | F5: Architecture | G5: Keep explicit ADR guardrails, create a dedicated Processes module, and review every Workbench field as projection-only. | H5: PRM-F01, PRM-F10
A6: R-PRM-02 | B6: CanvasLib overreach | C6: Process-specific demands force large CanvasLib changes that destabilize Prompt Factory or Project Structure. | D6: High | E6: Medium | F6: UI platform | G6: Start with adapter-level reuse, use group frames as v1 lanes, and phase link-label extensions only when proven necessary. | H6: PRM-F09
A7: R-PRM-03 | B7: Second scheduling language conflict | C7: Process orchestration, project execution context, and future agent-runtime choreography drift apart and create competing models for how work actually flows. | D7: High | E7: Medium | F7: Architecture | G7: Keep Processes canonical for collaboration/handoffs, keep Projects canonical for project scope/context, and use typed links plus PRM-F22/F23 guardrails instead of hidden duplicate scheduling logic. | H7: PRM-F10, PRM-F22, PRM-F23
A8: R-PRM-04 | B8: Agent identity duplication outside CRM-HR | C8: The process module starts persisting its own durable agent/person records instead of binding to CRM-HR. | D8: High | E8: Low | F8: CRM-HR | G8: Make CRM-HR binding mandatory for durable actors and keep process-side identities as references plus snapshots only. | H8: PRM-F03, PRM-F13
A9: R-PRM-05 | B9: SQLite runtime degradation | C9: Append-heavy run journals and step events grow faster than expected and SQLite performance drops for large projects. | D9: High | E9: Medium | F9: Persistence | G9: Index project/run/state paths, keep journal append-oriented, define retention/extraction boundaries early, and preserve PostgreSQL parity. | H9: PRM-F08, PRM-F15
A10: R-PRM-06 | B10: Ambiguous transition conditions | C10: Decision branches are modeled with free-text conditions that are too vague to test or audit. | D10: Medium | E10: Medium | F10: Process domain | G10: Separate display text from evaluator metadata, add validation rules, and require reason capture on branch selection. | H10: PRM-F05
A11: R-PRM-07 | B11: Approval model diverges from future agent rights | C11: Process approvals and escalations use shapes that later do not fit AgentFramework permission and approval semantics. | D11: Medium | E11: Medium | F11: Governance | G11: Align policy vocabulary now with explicit tool/collaboration/escalation approval concepts and keep a bridge seam rather than runtime coupling. | H11: PRM-F06, PRM-F13
A12: R-PRM-08 | B12: Diagram layout treated as truth | C12: Users or coders start inferring semantics from canvas position rather than canonical node/transition data. | D12: Medium | E12: Medium | F12: UI/Architecture | G12: Store layout separately, make semantic fields explicit, and test import/export without layout dependency. | H12: PRM-F09
A13: R-PRM-09 | B13: Mermaid round-trip loss | C13: Imported or exported Mermaid diagrams lose semantics such as approvals, actor roles, or structured contracts. | D13: Medium | E13: High | F13: Interop | G13: Import into draft only, emit explicit warnings, keep JSON package as the lossless format, and treat Mermaid as convenience interop. | H13: PRM-F12
A14: R-PRM-10 | B14: Insufficient audit trail for replay and training | C14: Important runtime changes are not journaled, making replay, supervision, and later evaluation incomplete. | D14: High | E14: Medium | F14: Runtime | G14: Define required event types early and verify journal coverage with integration tests and replay tests. | H14: PRM-F08, PRM-F14
A15: R-PRM-11 | B15: Automation before model stability | C15: The team tries to fully automate process execution before the base process language and governance model are stable. | D15: Medium | E15: Medium | F15: Delivery | G15: Prioritize manual and semi-automatic runtime first, then introduce AI executors through a bridge after the core state machine is proven. | H15: PRM-F07, PRM-F13
... A32: R-PRM-28 | B32: Canvas runtime overlay is mistaken for canonical state | C32: Developers or users assume live canvas overlays are the source of truth and start mutating process state through projection shortcuts. | D32: Medium | E32: Medium | F32: UI platform | G32: Keep overlay services read-only over canonical stores, mark projections explicitly in UI, and add tests that reject projection-only mutations. | H32: PRM-F24, PRM-F09

Sheet ADRs
A1: Architecture decisions
A2: High-level decisions intentionally locked by this process-first bundle.
A4: Decision ID | B4: Title | C4: Status | D4: Decision | E4: Rationale | F4: Related features
A5: ADR-PROC-001 | B5: Create a new canonical Processes module | C5: Accepted for bundle | D5: Process management is implemented as a new `CanDoItAll.Modules.Processes` module rather than extending Workbench or Prompt Factory as the canonical store. | E5: The repo already has ADR guardrails against turning Workbench into a hidden canonical model. | F5: PRM-F01, PRM-F10
A6: ADR-PROC-002 | B6: Use the shared application database first | C6: Accepted for bundle | D6: The first process-management release uses the main AppDbContext and both SQLite/PostgreSQL migration projects with `Processes_*` tables, not a separate per-project database. | E6: Direct module integrations (Projects, CRM-HR, Activity, Automation, Validation, TestLab) are simpler and safer with the current CanDoItAll storage pattern. Extraction remains a future seam. | F6: PRM-F01, PRM-F15
A7: ADR-PROC-003 | B7: CRM-HR owns durable actor identity | C7: Accepted for bundle | D7: The process module binds actor roles to CRM-HR parties and AI-agent profiles instead of maintaining a second durable actor registry. | E7: The uploaded CRM-HR module already models AI-agent profiles and project assignments as first-class business identity. | F7: PRM-F03, PRM-F13
A8: ADR-PROC-004 | B8: Workbench remains projection-only for process data | C8: Accepted for bundle | D8: Any Workbench support for processes is projection, navigation, or summary only; canonical process state stays in Processes tables. | E8: This follows the repo ADRs about projection-only metadata and node extension guardrails. | F8: PRM-F10
A9: ADR-PROC-005 | B9: Reuse CanvasLib and Prompt Factory patterns with minimal shared extensions | C9: Accepted for bundle | D9: The designer reuses CanvasLib and Prompt Factory adapter patterns first, and only introduces the smallest shared canvas changes needed for process diagrams. | E9: CanvasLib is already a shared owned foundation, but broad changes risk destabilizing existing consumers. | F9: PRM-F09
A10: ADR-PROC-006 | B10: Process runtime is AgentFramework-ready but not AgentFramework-dependent in v1 | C10: Accepted for bundle | D10: The first process runtime supports manual, human, and AI-capable roles through an execution bridge interface, but it does not take a direct dependency on the current AgentFramework repo. | E10: The user wants process management first and AgentFramework integration after/refactored later. | F10: PRM-F07, PRM-F13
A11: ADR-PROC-007 | B11: Store canonical graph semantics separately from diagram layout | C11: Accepted for bundle | D11: Nodes, transitions, policies, and contracts are normalized canonical data, while diagram coordinates, group frames, and UI state are stored separately as layout/projection data. | E11: This protects semantics from layout churn and supports multiple future visualizations. | F11: PRM-F02, PRM-F09
A12: ADR-PROC-008 | B12: Make runtime journaling explicit and append-oriented | C12: Accepted for bundle | D12: Important runtime changes are recorded as explicit journal events instead of inferred later from mutable current-state rows. | E12: Replay, supervision, and later training analysis depend on durable event history. | F12: PRM-F08, PRM-F14
A13: ADR-PROC-009 | B13: Support Mermaid and JSON package interop before BPMN | C13: Accepted for bundle | D13: The first interop target is Mermaid mindmap/flowchart plus a lossless JSON package; BPMN is deferred. | E13: The repo already contains Mermaid import/export patterns, while BPMN would significantly expand the semantic surface. | F13: PRM-F12
A14: ADR-PROC-010 | B14: Defer intelligence-lake implementation but preserve extension seams | C14: Accepted for bundle | D14: Process management ships first; training snapshots, curator loops, and future knowledge-lake integration are modeled as deferred hooks and insights outputs, not as first-wave dependencies. | E14: This matches the user's reprioritization and avoids blocking process delivery on the lake. | F14: PRM-F14
A15: ADR-PROC-011 | B15: Stage advanced parallel orchestration after sequential handoff core | C15: Accepted for bundle | D15: Sequential handoffs, decisions, approvals, and escalations ship before complex parallel joins, quorums, or group-chat-like runtime semantics. | E15: The current immediate need is explicit responsibilities and ordering for handoff collaboration, not maximum orchestration complexity. | F15: PRM-F05, PRM-F07
... A30: ADR-PROC-026 | B30: Separate project work breakdown from process orchestration while allowing typed links | C30: Accepted for bundle | D30: Projects remains the owner of project scope, hierarchy, and delivery context; Processes owns collaboration and handoff orchestration. Typed references may link runs or steps to project objects, but one model must not silently replace the other. | E30: The user wants process-modeled handoffs for actors, while the existing repo already uses Projects for broader execution context. These concerns must stay aligned without becoming a second hidden scheduling language. | F30: PRM-F10, PRM-F22, PRM-F23

Sheet Entities
A1: Canonical entities
A2: Recommended domain/storage entities for the Processes module and adjacent seams.
A4: Entity | B4: Kind | C4: Summary | D4: Tables | E4: Notes
A5: ProcessDefinition | B5: Canonical root | C5: Stable identity for a process family; owns scope, ownership, and version lineage. | D5: Processes_Definitions | E5: ProjectId nullable for workspace templates.
A6: ProcessDefinitionVersion | B6: Canonical version | C6: Immutable published or mutable draft version of a definition. | D6: Processes_DefinitionVersions | E6: One published version max per definition.
A7: ProcessNode | B7: Canonical graph node | C7: Start, step, decision, approval, handoff, wait, subprocess, or end node. | D7: Processes_Nodes | E7: Node kind drives validation rules.
A8: ProcessTransition | B8: Canonical graph edge | C8: Directed edge with branch semantics, labels, and default/conditional flags. | D8: Processes_Transitions | E8: Separate from diagram styling.
A9: ProcessActorRole | B9: Canonical role | C9: Named responsibility role used across one definition version. | D9: Processes_ActorRoles | E9: Examples: Triage, Architect, Reviewer.
A10: ProcessActorBinding | B10: Canonical binding | C10: Maps a role to CRM-HR party / AI-agent profile / fallback owner metadata. | D10: Processes_ActorBindings | E10: Binding changes are versioned/audited.
A11: ProcessStepContract | B11: Canonical contract | C11: Entry/exit criteria, instructions, evidence requirements, and SLO for a step node. | D11: Processes_StepContracts | E11: One contract per executable step node.
A12: ProcessArtifactContract | B12: Canonical contract child | C12: Typed input/output/evidence artifact expectation for a step. | D12: Processes_ArtifactContracts | E12: Tracks direction, type, required flag, notes.
A13: ProcessApprovalPolicy | B13: Canonical policy | C13: Approval requirements attached to a node or transition. | D13: Processes_ApprovalPolicies | E13: Supports pause/resume and approver routing.
A14: ProcessEscalationPolicy | B14: Canonical policy | C14: Escalation targets and timeout rules for blocked or failed work. | D14: Processes_EscalationPolicies | E14: Can target party or supervisory role.
A15: ProcessDiagramLayout | B15: Projection/layout | C15: Persisted diagram positions and editor UI state for one version. | D15: Processes_DiagramLayouts | E15: Never canonical semantic truth.
... A48: ProcessRuntimeOverlayProjection | B48: Projection model | C48: Read-only projection describing current run state on the authored diagram, including active nodes, waits, approvals, and baton visibility. | D48: Query projection / optional cache | E48: Never canonical runtime truth.

Sheet Integrations
A1: Integration seams
A2: Cross-module integration expectations for the process-management rollout.
A4: Module | B4: Current asset | C4: Integration | D4: Direction | E4: Wave | F4: Mandatory | G4: Sources
A5: Projects | B5: Project models, hierarchy, project UX, project modal/board | C5: Project-scoped processes, shared-project navigation, explicit process ownership for shared libraries/projects, and typed links from process definitions/runs/steps into project context without replacing project hierarchy. | D5: Processes -> Projects (reference ProjectId and context links); Projects UX -> Processes navigation | E5: Wave 1/3 | F5: Yes | G5: src/CanDoItAll.Modules.Projects/ProjectModels.cs; ProjectModalHost.razor; ProjectsBoard.razor
A6: CRM-HR | B6: Party directory, AI-agent profiles, project assignments, workforce/staffing primitives | C6: Actor role binding, owner/steward binding, manager-owned role and agent templates, durable AI identities, approvers, supervisory parties, staffing fulfillment, and future AI-executor mapping. | D6: Processes -> CRM-HR via bridge; CRM-HR owns identities, staffing templates, and AI business profiles | E6: Wave 1/2 | F6: Yes | G6: src/CanDoItAll.Modules.CrmHr/CrmHrBusinessModels.cs; CrmHrServices.cs; Pages/CrmHrAgentsPage.razor; Pages/CrmHrAssignmentsPage.razor
A7: CRM-HR Workforce / Recruiting / Assignments | B7: Staffing requests, workforce profiles, recruiting pipelines, onboarding tasks, capacity dashboard | C7: Manager-defined role templates, staffing briefs from process gaps, candidate/agent sourcing, capacity-aware suggestions, fallback handoffs, and capacity signals used by process telemetry. | D7: Processes <-> CRM-HR staffing bridges | E7: Wave 1/2 | F7: Yes | G7: src/CanDoItAll.Modules.CrmHr/CrmHrBusinessModels.cs; CrmHrServices.cs; CrmHrRecruitingServices.cs; Pages/CrmHrAssignmentsPage.razor; Pages/CrmHrRecruitingPage.razor; Pages/CrmHrWorkforcePage.razor
A8: Workspace | B8: Shared provider profiles, neutral provider contract, provider execution service, settings surface | C8: Future AI executor bindings and CRM-HR agent profiles must resolve through shared Workspace provider profiles instead of inventing a second permanent provider registry. | D8: Processes -> Workspace provider/profile references; CRM-HR and future AF bridge reuse Workspace truth | E8: Wave 1/3 | F8: Yes | G8: src/CanDoItAll.Modules.Workspace/WorkspaceModels.cs; ProviderExecution.cs; Pages/SettingsPage.razor
A9: Workbench | B9: Project structure surface, projection/bindings, leases, Mermaid import | C9: Optional process summary projections and navigation; import/export heuristics as reference only. | D9: Processes -> Workbench projection; never canonical reverse | E9: Wave 3 | F9: No | G9: architecture/adrs/ADR-0002*; ADR-0004*; ProjectStructureImportService.cs; ProjectStructureLeaseService.cs
A10: CanvasLib | B10: Interactive workbench-style canvas foundation | C10: Dedicated process designer surface, diagram layout, quick-create, minimap, grouping, possible link-label extension. | D10: Processes -> CanvasLib adapter | E10: Wave 1 | F10: Yes | G10: src/CanDoItAll.Components.CanvasLib/Canvas/Workbench/*
A11: Factory | B11: Prompt Flow templates and graph/canvas adapters | C11: Reference pattern for graph editor UX and optional starter template seeding from prompt-flow patterns. | D11: Processes <- Factory patterns / seeds | E11: Wave 1/2 | F11: No | G11: src/CanDoItAll.Modules.Factory/FactoryDomain.cs; CanvasAdapters/*; output/prompt-library/factory-prompt-flow-templates.seed.json
A12: Activity | B12: Shared activity timeline | C12: Record high-level run events, change-governance communications, and conformance review signals. | D12: Processes -> Activity via IActivityStream | E12: Wave 2/3/4 | F12: Yes | G12: src/CanDoItAll.SharedKernel/ActivityStream.cs; src/CanDoItAll.Modules.Activity/ActivityModels.cs
A13: Automation | B13: Background runtime and automation signals | C13: Overdue/blocker signals, governed change notifications, and later scheduled transitions or telemetry extraction jobs. | D13: Processes -> Automation signals | E13: Wave 3/4 | F13: No | G13: src/CanDoItAll.SharedKernel/AutomationSignals.cs; src/CanDoItAll.Modules.Automation/*
A14: Validation | B14: Validation center and review artifacts | C14: Attach validation gates, reviews, input-quality requirements, and evidence requirements to steps. | D14: Processes <-> Validation references | E14: Wave 3 | F14: No | G14: src/CanDoItAll.Modules.Validation/*
A15: TestLab | B15: Test plans and evidence | C15: Attach test plans/evidence to steps and completion gates. | D15: Processes <-> TestLab references | E15: Wave 3 | F15: No | G15: src/CanDoItAll.Modules.TestLab/*
... A19: AgentFramework overlay | B19: Research runtime, temporary template/provider/capability/session stores, rights model, sessions, execution logs, metrics | C19: Future AI-execution bridge, process-bound correlation, permission mapping, and registry convergence; business templates and durable identities stay outside the overlay. | D19: Future adapter only; Processes remains canonical for orchestration, CRM-HR/Workspace remain canonical for identities/templates/providers | E19: Wave 3+ | F19: No | G19: CanDoItAll.AgentFramework-main/integration-map/01-candoitall-seams.md; integration-map/02-data-rights-and-persistence.md; src/CanDoItAll.AgentFramework.Models/AgentModels.cs; src/CanDoItAll.AgentFramework.Models/ConversationModels.cs; src/CanDoItAll.AgentFramework.Core/AgentFrameworkWorkspaceService.Chat.cs

Sheet DeliveryWaves
A1: Delivery waves
A2: Recommended phased implementation order for Codex and the main team, including cross-cutting persistence hardening.
A4: Wave | B4: Goal | C4: Scope | D4: Entry criterion | E4: Exit criterion
A5: Wave 0 | B5: Design freeze and repo scaffolding | D5: Bundle approved | E5: Process module project exists; composition wired; architecture guardrails checked in.
A6: Wave 1 | B6: Canonical process modeling foundation | C6: PRM-F01, PRM-F02, PRM-F03, PRM-F16, PRM-F04, PRM-F17, PRM-F09 | D6: Wave 0 complete | E6: Users can create/publish draft processes, bind actors from CRM-HR, select reusable role templates, capture owner/customer/interface metadata, and edit diagrams on canvas.
A7: Cross-cutting | B7: Storage, migration, and performance guardrails across all waves | C7: PRM-F15 | D7: Process module foundation defined and runtime/journal modeling known | E7: Shared-database persistence, indexing, retention seams, and dual SQLite/PostgreSQL support remain healthy through all waves.
A8: Wave 2 | B8: Runtime handoffs, baton orchestration, and governance core | C8: PRM-F05, PRM-F06, PRM-F07, PRM-F08, PRM-F18, PRM-F22, PRM-F12 | D8: Wave 1 complete | E8: Users can start runs, enforce approval/decision-right rules, route governed baton handoffs and triage decisions, handle bad inputs and exceptions, and inspect journals.
A9: Wave 3 | B9: Cross-module integration, live supervision, and future AI convergence seams | C9: PRM-F10, PRM-F11, PRM-F13, PRM-F24, PRM-F23, PRM-F20 | D9: Wave 2 complete | E9: Project UX, activity/automation hooks, live runtime canvas overlays, future AI bridge seams, and cross-repo convergence rules are integrated without surrendering canonical ownership.
A10: Wave 4 | B10: Operational intelligence and conformance loop | C10: PRM-F19, PRM-F14, PRM-F21 | D10: Wave 3 complete | E10: Outcome telemetry, bottleneck insights, improvement candidates, and paper-versus-reality reviews exist without requiring the intelligence lake.

Sheet Traceability
A1: Traceability
A2: Feature-level traceability to user stories, decisions, risks, touchpoints, and wave planning.
A4: Feature ID | B4: Title | C4: Wave | D4: User story count | E4: Decision IDs | F4: Risk IDs | G4: Touchpoint count | H4: Notes
A5: PRM-F01 | B5: Process module foundation and shell integration | C5: Wave 1 | D5: =COUNTIF(UserStories!B:B,A5) | E5: ADR-PROC-001, ADR-PROC-002 | F5: R-PRM-01 | G5: 11 | H5: See subbundle and manifest for implementation detail.
A6: PRM-F02 | B6: Process definition language and versioning | C6: Wave 1 | D6: =COUNTIF(UserStories!B:B,A6) | E6: ADR-PROC-007, ADR-PROC-013 | F6: R-PRM-03, R-PRM-14 | G6: 4 | H6: See subbundle and manifest for implementation detail.
A7: PRM-F03 | B7: Actor roles, responsibilities, and CRM-HR bindings | C7: Wave 1 | D7: =COUNTIF(UserStories!B:B,A7) | E7: ADR-PROC-003, ADR-PROC-012 | F7: R-PRM-04, R-PRM-12, R-PRM-15 | G7: 4 | H7: See subbundle and manifest for implementation detail.
A8: PRM-F16 | B8: Role and agent templates, staffing briefs, and sourcing handoffs | C8: Wave 1 | D8: =COUNTIF(UserStories!B:B,A8) | E8: ADR-PROC-012, ADR-PROC-013, ADR-PROC-014, ADR-PROC-022 | F8: R-PRM-15, R-PRM-17, R-PRM-24 | G8: 11 | H8: See subbundle and manifest for implementation detail.
A9: PRM-F04 | B9: Step contracts, inputs, outputs, and evidence | C9: Wave 1 | D9: =COUNTIF(UserStories!B:B,A9) | G9: 1 | H9: See subbundle and manifest for implementation detail.
A10: PRM-F17 | B10: Process ownership, interfaces, customer, and value alignment | C10: Wave 1 | D10: =COUNTIF(UserStories!B:B,A10) | E10: ADR-PROC-015, ADR-PROC-016 | F10: R-PRM-18 | G10: 7 | H10: See subbundle and manifest for implementation detail.
A11: PRM-F09 | B11: Canvas modeler and interactive diagrams | C11: Wave 1 | D11: =COUNTIF(UserStories!B:B,A11) | E11: ADR-PROC-005, ADR-PROC-007, ADR-PROC-014 | F11: R-PRM-02, R-PRM-08 | G11: 9 | H11: See subbundle and manifest for implementation detail.
A12: PRM-F15 | B12: Storage, migrations, and performance hardening | C12: Cross-cutting | D12: =COUNTIF(UserStories!B:B,A12) | E12: ADR-PROC-002 | F12: R-PRM-05 | G12: 3 | H12: See subbundle and manifest for implementation detail.
A13: PRM-F05 | B13: Transition rules, decisions, and explicit handoffs | C13: Wave 2 | D13: =COUNTIF(UserStories!B:B,A13) | E13: ADR-PROC-011, ADR-PROC-014 | F13: R-PRM-06, R-PRM-13 | G13: 2 | H13: See subbundle and manifest for implementation detail.
A14: PRM-F06 | B14: Approval policies, escalations, and governance gates | C14: Wave 2 | D14: =COUNTIF(UserStories!B:B,A14) | F14: R-PRM-07, R-PRM-16 | G14: 1 | H14: See subbundle and manifest for implementation detail.
A15: PRM-F07 | B15: Runtime execution state machine and assignments | C15: Wave 2 | D15: =COUNTIF(UserStories!B:B,A15) | E15: ADR-PROC-006, ADR-PROC-011, ADR-PROC-013 | F15: R-PRM-03, R-PRM-11, R-PRM-13, R-PRM-16, R-PRM-17 | G15: 5 | H15: See subbundle and manifest for implementation detail.
A16: PRM-F08 | B16: Execution timeline, audit journal, and replay | C16: Wave 2 | D16: =COUNTIF(UserStories!B:B,A16) | E16: ADR-PROC-008 | F16: R-PRM-05, R-PRM-10 | G16: 4 | H16: See subbundle and manifest for implementation detail.
A17: PRM-F18 | B17: Variants, exceptions, input quality, and decision rights | C17: Wave 2 | D17: =COUNTIF(UserStories!B:B,A17) | E17: ADR-PROC-017 | F17: R-PRM-20, R-PRM-22 | G17: 7 | H17: See subbundle and manifest for implementation detail.
A18: PRM-F22 | B18: Process-native work briefs, baton handoffs, and governed triage routing | C18: Wave 2 | D18: =COUNTIF(UserStories!B:B,A18) | E18: ADR-PROC-021, ADR-PROC-023, ADR-PROC-026 | F18: R-PRM-25, R-PRM-03, R-PRM-10 | G18: 8 | H18: See subbundle and manifest for implementation detail.
A19: PRM-F12 | B19: Import/export, templates, Mermaid, and prompt-flow seeding | C19: Wave 2 | D19: =COUNTIF(UserStories!B:B,A19) | E19: ADR-PROC-009 | F19: R-PRM-09, R-PRM-14 | G19: 2 | H19: See subbundle and manifest for implementation detail.
A20: PRM-F10 | B20: Project, Workbench, and shell projections | C20: Wave 3 | D20: =COUNTIF(UserStories!B:B,A20) | E20: ADR-PROC-001, ADR-PROC-004, ADR-PROC-026 | F20: R-PRM-01, R-PRM-12, R-PRM-14, R-PRM-03 | G20: 8 | H20: See subbundle and manifest for implementation detail.
A21: PRM-F11 | B21: Activity, Automation, Validation, and TestLab hooks | C21: Wave 3 | D21: =COUNTIF(UserStories!B:B,A21) | F21: R-PRM-12 | G21: 3 | H21: See subbundle and manifest for implementation detail.
A22: PRM-F13 | B22: Future AgentFramework adapter and AI executor seam | C22: Wave 3 | D22: =COUNTIF(UserStories!B:B,A22) | E22: ADR-PROC-003, ADR-PROC-006, ADR-PROC-012, ADR-PROC-022, ADR-PROC-023, ADR-PROC-024 | F22: R-PRM-03, R-PRM-04, R-PRM-07, R-PRM-11, R-PRM-26, R-PRM-27 | G22: 3 | H22: See subbundle and manifest for implementation detail.
A23: PRM-F24 | B23: Live process execution canvas overlays and baton visibility | C23: Wave 3 | D23: =COUNTIF(UserStories!B:B,A23) | E23: ADR-PROC-005, ADR-PROC-025 | F23: R-PRM-28, R-PRM-08, R-PRM-02 | G23: 6 | H23: See subbundle and manifest for implementation detail.
A24: PRM-F23 | B24: AgentFramework convergence: process-bound context, rights, and shared registries | C24: Wave 3 | D24: =COUNTIF(UserStories!B:B,A24) | E24: ADR-PROC-006, ADR-PROC-022, ADR-PROC-023, ADR-PROC-024, ADR-PROC-026 | F24: R-PRM-24, R-PRM-26, R-PRM-27, R-PRM-03 | G24: 8 | H24: See subbundle and manifest for implementation detail.
A25: PRM-F20 | B25: Change governance, prioritization, literacy, and management adoption | C25: Wave 3 | D25: =COUNTIF(UserStories!B:B,A25) | E25: ADR-PROC-019 | F25: R-PRM-18, R-PRM-21, R-PRM-22 | G25: 6 | H25: See subbundle and manifest for implementation detail.
A26: PRM-F19 | B26: Outcome metrics, capacity, wait-state telemetry, and customer-value measures | C26: Wave 4 | D26: =COUNTIF(UserStories!B:B,A26) | E26: ADR-PROC-018 | F26: R-PRM-19 | G26: 6 | H26: See subbundle and manifest for implementation detail.
A27: PRM-F14 | B27: Operational intelligence, improvement backlog, and training-opportunity loop | C27: Wave 4 | D27: =COUNTIF(UserStories!B:B,A27) | E27: ADR-PROC-008, ADR-PROC-010 | F27: R-PRM-10 | G27: 3 | H27: See subbundle and manifest for implementation detail.
A28: PRM-F21 | B28: Conformance, field observation, and reality-alignment reviews | C28: Wave 4 | D28: =COUNTIF(UserStories!B:B,A28) | E28: ADR-PROC-020 | F28: R-PRM-20, R-PRM-23 | G28: 6 | H28: See subbundle and manifest for implementation detail.

Sheet OperationalCoverage
A1: Operational coverage
A2: Mapping of commonly overlooked large-enterprise process-management factors to explicit bundle responses.
A4: ID | B4: Concern | C4: Why it matters | D4: Bundle response | E4: Mapped features | F4: Guardrail / note
A5: OP-01 | B5: Jasné vlastnictví procesu | C5: Bez skutečného end-to-end ownera se problémy přehazují mezi útvary. | D5: Publish guardrails pro process owner/customer/value statement + governance profile. | E5: PRM-F17, PRM-F20 | F5: Owner je povinný pro governed publish; stewardship může být víceúrovňový.
A6: OP-02 | B6: End-to-end pohled místo pohledu oddělení | C6: Největší ztráty vznikají na předávkách mezi týmy. | D6: Interface contracts, upstream/downstream boundaries, done definitions, interface telemetry. | E6: PRM-F17, PRM-F19 | F6: Rozhraní jsou samostatné artefakty, ne jen poznámka v diagramu.
A7: OP-03 | B7: Rozdíl mezi procesem a organizační strukturou | C7: Org chart není totéž co tok hodnoty. | D7: ADR odděluje value flow od reporting lines; role binding jde přes CRM-HR bez vnucení hierarchie. | E7: PRM-F03, PRM-F17 | F7: Graf procesu nesmí kopírovat org chart pouze proto, že existuje.
A8: OP-04 | B8: Měření správných metrik | C8: Aktivita není výsledek. | D8: Outcome telemetry: lead/touch/queue time, first-time-right, rework, customer signal. | E8: PRM-F19, PRM-F14 | F8: Dashboard nesmí vydávat activity counts za hlavní KPI.
A9: OP-05 | B9: Variabilita a výjimky | C9: Happy path nestačí pro reálný provoz. | D9: Approved variants, exception playbooks, override reasons, escalation handling. | E9: PRM-F18, PRM-F21 | F9: Výjimky jsou modelované, journalované a reviewovatelné.
A10: OP-06 | B10: Kvalita vstupů do procesu | C10: Garbage in, garbage out. | D10: Input-quality rules, completeness checks, triage classification, rework reasons. | E10: PRM-F04, PRM-F18 | F10: Vstupní kvalita je kontrolovatelná před pokračováním procesu.
A11: OP-07 | B11: Procesní disciplína vs. procesní byrokracie | C11: Příliš mnoho kontrol vede k obcházení procesu. | D11: Risk-tiered controls and rationalization review. | E11: PRM-F18, PRM-F20 | F11: Nízkoriziková práce nemá být utopená v approvals.
A12: OP-08 | B12: Role středního managementu | C12: Bez aktivní podpory středního managementu proces formálně žije, ale reálně ne. | D12: Stewardship roles, change acknowledgements, management adoption flows. | E12: PRM-F17, PRM-F20 | F12: Manager není jen approver, ale steward/adoption owner.
A13: OP-09 | B13: Reálná práce vs. proces na papíře | C13: Oficiální diagram může být fikce. | D13: Conformance observations, deviation clustering, paper-vs-reality reviews. | E13: PRM-F21 | F13: Základem je evidence z run journalu a řízené terénní pozorování.
A14: OP-10 | B14: Rozhraní mezi procesy | C14: Nejasný konec a začátek procesů vytváří chaos. | D14: Explicit process interface contracts and done definitions. | E14: PRM-F17 | F14: Styčné plochy mají vstupy, výstupy a převzetí odpovědnosti.
A15: OP-11 | B15: Prioritizace procesů | C15: Ne vše musí být modelováno stejně hluboko. | D15: Criticality tiers and portfolio prioritization. | E15: PRM-F17, PRM-F20 | F15: Governance hloubka se odvíjí od criticality a business impact.
... A26: OP-22 | B26: Dvojí registry a osiřelý runtime kontext | C26: Oddělené registry template/provider/capability a nesvázané runtime sessions vedou k chaosu, neauditovatelnosti a driftu mezi business a runtime vrstvou. | D26: CRM-HR/Workspace canonical ownership, external execution correlations, and explicit AgentFramework convergence rules. | E26: PRM-F23, PRM-F16, PRM-F13 | F26: Runtime může být externí, ale business truth a correlation zůstávají v CanDoItAll.

Sheet SeniorReviews
A1: Senior review outcomes
A2: Final senior process-manager, quality-inspector, and C# architect findings closed in this bundle revision.
